Workbook
Name ИменованныйДиапазон1: ПОНЕДЕЛЬНИК!$B$3

Sheet итог
C3: ТОЛЬКО ПОНЕДЕЛЬНИК!!! | G3: РАСПИСАНИЕ ЗАНЯТИЙ | K3: У Т В Е Р Ж Д А Ю:
C4: кл. час | D4: 9.00-10.00 | K4: Директор техникума ___________
C5: 1 пара | D5: 10.00-11.30 | E5: 1 пара | F5: 9.00-10.30 | K5: «_____» ______________2024 г.
C6: 2 пара | D6: 11.40-12.25 13.10-13.55 | E6: 2 пара | F6: 10.50-12.20 12.20-13.05 | G6: ОБЕД (для 1 и 3 курса 11.35-12.20) | H6: ОБЕД (для 2 и 4 курса 12.20-13.15)
C7: 3 пара | D7: 14.05-15.35 | E7: 3 пара | F7: 13.15-14.45
C8: 4 пара | D8: 15.45-17.15 | E8: 4 пара | F8: 14.55-16.25
E9: 5 пара | F9: 16.35-18.05
C11: 101эм | D11: 129э | E11: 130э | F11: 131э | G11: 175р | H11: 176р | I11: 172т | J11: 121ос | K11: 224э | L11: 225э | M11: 226э | N11: 227э | O11: 128эу | P11: 272р | Q11: 273р | R11: 174ру | S11: 271т | T11: 220ос | U11: 319э | V11: 320э | W11: 321э | X11: 223эу | Y11: 369р | Z11: 370р | AA11: 271ру | AB11: 370т | AC11: 319ос | AD11: 414э | AE11: 416э | AF11: 466р | AG11: 467р | AH11: 368ру | AI11: 469т | AJ11: 418Ос
A12: ПОНЕДЕЛЬНИК | B12: 1 | C12: =ПОНЕДЕЛЬНИК!B3 -> Физика/104 | D12: =ПОНЕДЕЛЬНИК!B4 -> Иностран. язык/312/314 | E12: =ПОНЕДЕЛЬНИК!B5 -> Биология/228 | F12: =ПОНЕДЕЛЬНИК!P3 -> 0 | G12: =ПОНЕДЕЛЬНИК!B7 -> Проект.деят/411(Щ) | H12: =ПОНЕДЕЛЬНИК!B8 -> Физика/416 | I12: =ПОНЕДЕЛЬНИК!B9 -> Физика/300 | J12: =ПОНЕДЕЛЬНИК!B10 -> Русский язык/404 | K12: =ПОНЕДЕЛЬНИК!B11 -> Математика/227 | L12: =ПОНЕДЕЛЬНИК!B12 -> Информатика/400 | M12: =ПОНЕДЕЛЬНИК!B13 -> История/310 | N12: =ПОНЕДЕЛЬНИК!B14 -> Биология/406 | O12: =ПОНЕДЕЛЬНИК!B15 -> География/201 | P12: =ПОНЕДЕЛЬНИК!B16 -> Математика/419 | Q12: =ПОНЕДЕЛЬНИК!B17 -> 0 | R12: =ПОНЕДЕЛЬНИК!AB3 -> 0 | S12: =ПОНЕДЕЛЬНИК!AC3 -> 0 | T12: =ПОНЕДЕЛЬНИК!AD3 -> 0 | U12: =ПОНЕДЕЛЬНИК!AE3 -> 0 | V12: =ПОНЕДЕЛЬНИК!AF3 -> 0 | W12: =ПОНЕДЕЛЬНИК!AG3 -> 0 | X12: =ПОНЕДЕЛЬНИК!AH3 -> 0 | Y12: =ПОНЕДЕЛЬНИК!AI3 -> 0 | ... AI12: =ПОНЕДЕЛЬНИК!AS3 -> 0 | AJ12: =ПОНЕДЕЛЬНИК!B36 -> Психология/401
B13: 2 | C13: =ПОНЕДЕЛЬНИК!C3 -> Математика/227 | D13: =ПОНЕДЕЛЬНИК!C4 -> Русский язык/228 | E13: =ПОНЕДЕЛЬНИК!C5 -> Физика/416 | F13: =ПОНЕДЕЛЬНИК!C6 -> Русский язык/404 | G13: =ПОНЕДЕЛЬНИК!C7 -> Математика/405 | H13: =ПОНЕДЕЛЬНИК!C8 -> История/310 | I13: =ПОНЕДЕЛЬНИК!C9 -> Физика/300 | J13: =ПОНЕДЕЛЬНИК!C10 -> Математика/419 | K13: =ПОНЕДЕЛЬНИК!C11 -> Информатика/400 | L13: =ПОНЕДЕЛЬНИК!C12 -> Обществознание/411 | M13: =ПОНЕДЕЛЬНИК!C13 -> Биология/406 | N13: =ПОНЕДЕЛЬНИК!C14 -> Физика/104 | O13: =ПОНЕДЕЛЬНИК!C15 -> Иностран. язык/312/314 | P13: =ПОНЕДЕЛЬНИК!C16 -> География/201 | Q13: =ПОНЕДЕЛЬНИК!C17 -> 0 | R13: =ПОНЕДЕЛЬНИК!AB4 -> 0 | S13: =ПОНЕДЕЛЬНИК!AC4 -> 0 | T13: =ПОНЕДЕЛЬНИК!AD4 -> 0 | U13: =ПОНЕДЕЛЬНИК!AE4 -> 0 | V13: =ПОНЕДЕЛЬНИК!AF4 -> 0 | W13: =ПОНЕДЕЛЬНИК!AG4 -> 0 | X13: =ПОНЕДЕЛЬНИК!AH4 -> 0 | Y13: =ПОНЕДЕЛЬНИК!AI4 -> 0 | ... AI13: =ПОНЕДЕЛЬНИК!AS4 -> 0 | AJ13: =ПОНЕДЕЛЬНИК!C36 -> ПМ03/423
B14: 3 | C14: =ПОНЕДЕЛЬНИК!D3 -> История/310 | D14: =ПОНЕДЕЛЬНИК!D4 -> Химия/406 | E14: =ПОНЕДЕЛЬНИК!D5 -> Математика/405 | F14: =ПОНЕДЕЛЬНИК!D6 -> Информатика/226 | G14: =ПОНЕДЕЛЬНИК!D7 -> Биология/228 | H14: =ПОНЕДЕЛЬНИК!D8 -> Проект.деят/317(Б) | I14: =ПОНЕДЕЛЬНИК!D9 -> Русский язык/404 | J14: =ПОНЕДЕЛЬНИК!D10 -> Иностран. язык/312/б-ка | K14: =ПОНЕДЕЛЬНИК!D11 -> Обществознание/411 | L14: =ПОНЕДЕЛЬНИК!D12 -> Математика/227 | M14: =ПОНЕДЕЛЬНИК!D13 -> Физика/104 | N14: =ПОНЕДЕЛЬНИК!D14 -> География/201 | O14: =ПОНЕДЕЛЬНИК!D15 -> Математика/419 | P14: =ПОНЕДЕЛЬНИК!D16 -> Физика/416 | Q14: =ПОНЕДЕЛЬНИК!D17 -> Физкультура | R14: =ПОНЕДЕЛЬНИК!AB5 -> 0 | S14: =ПОНЕДЕЛЬНИК!AC5 -> 0 | T14: =ПОНЕДЕЛЬНИК!AD5 -> 0 | U14: =ПОНЕДЕЛЬНИК!AE5 -> 0 | V14: =ПОНЕДЕЛЬНИК!AF5 -> 0 | W14: =ПОНЕДЕЛЬНИК!AG5 -> 0 | X14: =ПОНЕДЕЛЬНИК!AH5 -> 0 | Y14: =ПОНЕДЕЛЬНИК!AI5 -> 0 | ... AI14: =ПОНЕДЕЛЬНИК!AS5 -> 0 | AJ14: =ПОНЕДЕЛЬНИК!D36 -> ПМ 01/301(К)
A15: =ПОНЕДЕЛЬНИК!D1 -> 46307 | B15: 4 | C15: =ПОНЕДЕЛЬНИК!M6 -> 0 | D15: =ПОНЕДЕЛЬНИК!N6 -> 0 | E15: =ПОНЕДЕЛЬНИК!E5 -> 0 | F15: =ПОНЕДЕЛЬНИК!P6 -> 0 | G15: =ПОНЕДЕЛЬНИК!E7 -> 0 | I15: =ПОНЕДЕЛЬНИК!S6 -> 0 | J15: =ПОНЕДЕЛЬНИК!T6 -> 0 | K15: =ПОНЕДЕЛЬНИК!U6 -> 0 | L15: =ПОНЕДЕЛЬНИК!V6 -> 0 | M15: =ПОНЕДЕЛЬНИК!W6 -> 0 | N15: =ПОНЕДЕЛЬНИК!E14 -> 0 | O15: =ПОНЕДЕЛЬНИК!Y6 -> 0 | P15: =ПОНЕДЕЛЬНИК!Z6 -> 0 | Q15: =ПОНЕДЕЛЬНИК!E17 -> Математика/419 | R15: =ПОНЕДЕЛЬНИК!AB6 -> 0 | S15: =ПОНЕДЕЛЬНИК!AC6 -> 0 | T15: =ПОНЕДЕЛЬНИК!AD6 -> 0 | U15: =ПОНЕДЕЛЬНИК!AE6 -> 0 | V15: =ПОНЕДЕЛЬНИК!AF6 -> 0 | W15: =ПОНЕДЕЛЬНИК!AG6 -> 0 | X15: =ПОНЕДЕЛЬНИК!AH6 -> 0 | Y15: =ПОНЕДЕЛЬНИК!AI6 -> 0 | ... AI15: =ПОНЕДЕЛЬНИК!AS6 -> 0 | AJ15: =ПОНЕДЕЛЬНИК!E36 -> 0
B16: 5 | C16: =ПОНЕДЕЛЬНИК!M7 -> 0 | D16: =ПОНЕДЕЛЬНИК!N7 -> 0 | E16: =ПОНЕДЕЛЬНИК!O7 -> Выбор оборуд./309 | F16: =ПОНЕДЕЛЬНИК!P7 -> 0 | G16: =ПОНЕДЕЛЬНИК!Q7 -> 0 | H16: =ПОНЕДЕЛЬНИК!R7 -> 0 | I16: =ПОНЕДЕЛЬНИК!S7 -> 0 | J16: =ПОНЕДЕЛЬНИК!T7 -> 0 | ... M16: =ПОНЕДЕЛЬНИК!W7 -> 0 | N16: =ПОНЕДЕЛЬНИК!F14 -> 0 | O16: =ПОНЕДЕЛЬНИК!Y7 -> 0 | P16: =ПОНЕДЕЛЬНИК!Z7 -> 0 | Q16: =ПОНЕДЕЛЬНИК!F17 -> ТОТ/101 | R16: =ПОНЕДЕЛЬНИК!AB7 -> 0 | S16: =ПОНЕДЕЛЬНИК!AC7 -> 0 | T16: =ПОНЕДЕЛЬНИК!AD7 -> 0 | U16: =ПОНЕДЕЛЬНИК!AE7 -> 0 | V16: =ПОНЕДЕЛЬНИК!AF7 -> 0 | W16: =ПОНЕДЕЛЬНИК!AG7 -> 0 | X16: =ПОНЕДЕЛЬНИК!AH7 -> 0 | Y16: =ПОНЕДЕЛЬНИК!AI7 -> 0 | ... AI16: =ПОНЕДЕЛЬНИК!AS7 -> 0 | AJ16: =ПОНЕДЕЛЬНИК!F36 -> 0
C17: вт | D17: вт | E17: вт | F17: вт | G17: вт | H17: вт | I17: вт | J17: вт | K17: вт | L17: вт | M17: вт | N17: вт | O17: вт | P17: вт | Q17: вт | R17: вт | S17: вт | T17: вт | U17: вт | V17: вт | W17: вт | X17: вт | Y17: вт | Z17: вт | AA17: вт | AB17: вт | AC17: вт | AD17: вт | AE17: вт | AF17: вт | AG17: вт | AH17: вт | AI17: вт | AJ17: вт
A18: ВТОРНИК | B18: 1 | C18: =ВТОРНИК!M3 -> 0 | D18: =ВТОРНИК!N3 -> 0 | E18: =ВТОРНИК!O3 -> Аналит.хим./256 | F18: =ВТОРНИК!P3 -> 0 | G18: =ВТОРНИК!Q3 -> 0 | H18: =ВТОРНИК!R3 -> 0 | I18: =ВТОРНИК!S3 -> 0 | J18: =ВТОРНИК!T3 -> 0 | ... AI18: =ВТОРНИК!AS3 -> 0 | AJ18: =ВТОРНИК!B36 -> 0
B19: 2 | C19: =ВТОРНИК!M4 -> 0 | D19: =ВТОРНИК!N4 -> 0 | E19: =ВТОРНИК!O4 -> БЖД/231 | F19: =ВТОРНИК!P4 -> 0 | G19: =ВТОРНИК!Q4 -> 0 | H19: =ВТОРНИК!R4 -> 0 | I19: =ВТОРНИК!S4 -> 0 | J19: =ВТОРНИК!T4 -> 0 | ... AI19: =ВТОРНИК!AS4 -> 0 | AJ19: =ВТОРНИК!C36 -> 0
B20: 3 | C20: =ВТОРНИК!M5 -> 0 | D20: =ВТОРНИК!N5 -> 0 | E20: =ВТОРНИК!O5 -> Биология/228 | F20: =ВТОРНИК!P5 -> 0 | G20: =ВТОРНИК!Q5 -> 0 | H20: =ВТОРНИК!R5 -> 0 | I20: =ВТОРНИК!S5 -> 0 | J20: =ВТОРНИК!T5 -> 0 | ... AI20: =ВТОРНИК!AS5 -> 0 | AJ20: =ВТОРНИК!D36 -> 0
A21: =ВТОРНИК!D1 -> 46308 | B21: 4 | C21: =ВТОРНИК!M6 -> 0 | D21: =ВТОРНИК!N6 -> 0 | E21: =ВТОРНИК!O6 -> Биология/406 | F21: =ВТОРНИК!P6 -> 0 | G21: =ВТОРНИК!Q6 -> 0 | H21: =ВТОРНИК!R6 -> 0 | I21: =ВТОРНИК!S6 -> 0 | J21: =ВТОРНИК!T6 -> 0 | ... AI21: =ВТОРНИК!AS6 -> 0 | AJ21: =ВТОРНИК!E36 -> 0
B22: 5 | C22: =ВТОРНИК!M7 -> 0 | D22: =ВТОРНИК!N7 -> 0 | E22: =ВТОРНИК!O7 -> Выбор оборуд./309 | F22: =ВТОРНИК!P7 -> 0 | G22: =ВТОРНИК!Q7 -> 0 | H22: =ВТОРНИК!R7 -> 0 | I22: =ВТОРНИК!S7 -> 0 | J22: =ВТОРНИК!T7 -> 0 | ... AI22: =ВТОРНИК!AS7 -> 0 | AJ22: =ВТОРНИК!F36 -> ПМ05/318
C23: ср | D23: ср | E23: ср | F23: ср | G23: ср | H23: ср | I23: ср | J23: ср | K23: ср | L23: ср | M23: ср | N23: ср | O23: ср | P23: ср | Q23: ср | R23: ср | S23: ср | T23: ср | U23: ср | V23: ср | W23: ср | X23: ср | Y23: ср | Z23: ср | AA23: ср | AB23: ср | AC23: ср | AD23: ср | AE23: ср | AF23: ср | AG23: ср | AH23: ср | AI23: ср | AJ23: ср
A24: СРЕДА | B24: 1 | C24: =СРЕДА!L3 -> 0 | D24: =СРЕДА!M3 -> 0 | E24: =СРЕДА!N3 -> 0 | F24: =СРЕДА!O3 -> Аналит.хим./256 | G24: =СРЕДА!P3 -> 0 | H24: =СРЕДА!Q3 -> 0 | I24: =СРЕДА!R3 -> 0 | J24: =СРЕДА!S3 -> 0 | ... AI24: =СРЕДА!AR3 -> 0 | AJ24: =СРЕДА!B36 -> ПМ03/423
B25: 2 | C25: =СРЕДА!L4 -> 0 | D25: =СРЕДА!M4 -> 0 | E25: =СРЕДА!N4 -> 0 | F25: =СРЕДА!O4 -> БЖД/231 | G25: =СРЕДА!P4 -> 0 | H25: =СРЕДА!Q4 -> 0 | I25: =СРЕДА!R4 -> 0 | J25: =СРЕДА!S4 -> 0 | ... AI25: =СРЕДА!AR4 -> 0 | AJ25: =ВТОРНИК!C36 -> 0
B26: 3 | C26: =СРЕДА!L5 -> 0 | D26: =СРЕДА!M5 -> 0 | E26: =СРЕДА!N5 -> 0 | F26: =СРЕДА!O5 -> Биология/228 | G26: =СРЕДА!P5 -> 0 | H26: =СРЕДА!Q5 -> 0 | I26: =СРЕДА!R5 -> 0 | J26: =СРЕДА!S5 -> 0 | ... AI26: =СРЕДА!AR5 -> 0 | AJ26: =СРЕДА!D36 -> ПМ 01/317(К)
A27: =СРЕДА!D1 -> 46309 | B27: 4 | C27: =СРЕДА!L6 -> 0 | D27: =СРЕДА!M6 -> 0 | E27: =СРЕДА!N6 -> 0 | F27: =СРЕДА!O6 -> Биология/406 | G27: =СРЕДА!P6 -> 0 | H27: =СРЕДА!Q6 -> 0 | I27: =СРЕДА!R6 -> 0 | J27: =СРЕДА!S6 -> 0 | ... AI27: =СРЕДА!AR6 -> 0 | AJ27: =СРЕДА!E36 -> 0
B28: 5 | C28: =СРЕДА!L7 -> 0 | D28: =СРЕДА!M7 -> 0 | E28: =СРЕДА!N7 -> 0 | F28: =СРЕДА!O7 -> Выбор оборуд./309 | G28: =СРЕДА!P7 -> 0 | H28: =СРЕДА!Q7 -> 0 | I28: =СРЕДА!R7 -> 0 | J28: =СРЕДА!S7 -> 0 | ... AI28: =СРЕДА!AR7 -> 0 | AJ28: =СРЕДА!F36 -> 0
C29: чт | D29: чт | E29: чт | F29: чт | G29: чт | H29: чт | I29: чт | J29: чт | K29: чт | L29: чт | M29: чт | N29: чт | O29: чт | P29: чт | Q29: чт | R29: чт | S29: чт | T29: чт | U29: чт | V29: чт | W29: чт | X29: чт | Y29: чт | Z29: чт | AA29: чт | AB29: чт | AC29: чт | AD29: чт | AE29: чт | AF29: чт | AG29: чт | AH29: чт | AI29: чт | AJ29: чт
A30: ЧЕТВЕРГ | B30: 1 | C30: =ЧЕТВЕРГ!M2 -> 0 | D30: =ЧЕТВЕРГ!N2 -> 0 | E30: =ЧЕТВЕРГ!O2 -> 0 | F30: =ЧЕТВЕРГ!P2 -> 0 | G30: =ЧЕТВЕРГ!Q2 -> 0 | H30: =ЧЕТВЕРГ!R2 -> 0 | I30: =ЧЕТВЕРГ!S2 -> 0 | J30: =ЧЕТВЕРГ!T2 -> 0 | ... AI30: =ЧЕТВЕРГ!AS2 -> 0 | AJ30: =#REF! -> #REF!
B31: 2 | C31: =ЧЕТВЕРГ!M3 -> 0 | D31: =ЧЕТВЕРГ!N3 -> 0 | E31: =ЧЕТВЕРГ!O3 -> Аналит.хим./256 | F31: =ЧЕТВЕРГ!P3 -> 0 | G31: =ЧЕТВЕРГ!Q3 -> 0 | H31: =ЧЕТВЕРГ!R3 -> 0 | I31: =ЧЕТВЕРГ!S3 -> 0 | J31: =ЧЕТВЕРГ!T3 -> 0 | ... AI31: =ЧЕТВЕРГ!AS3 -> 0 | AJ31: =#REF! -> #REF!
B32: 3 | C32: =ЧЕТВЕРГ!M4 -> 0 | D32: =ЧЕТВЕРГ!N4 -> 0 | E32: =ЧЕТВЕРГ!O4 -> БЖД/231 | F32: =ЧЕТВЕРГ!P4 -> 0 | G32: =ЧЕТВЕРГ!Q4 -> 0 | H32: =ЧЕТВЕРГ!R4 -> 0 | I32: =ЧЕТВЕРГ!S4 -> 0 | J32: =ЧЕТВЕРГ!T4 -> 0 | ... AI32: =ЧЕТВЕРГ!AS4 -> 0 | AJ32: =#REF! -> #REF!
A33: =ЧЕТВЕРГ!D1 -> 46310 | B33: 4 | C33: =ЧЕТВЕРГ!M5 -> 0 | D33: =ЧЕТВЕРГ!N5 -> 0 | E33: =ЧЕТВЕРГ!O5 -> Биология/228 | F33: =ЧЕТВЕРГ!P5 -> 0 | G33: =ЧЕТВЕРГ!Q5 -> 0 | H33: =ЧЕТВЕРГ!R5 -> 0 | I33: =ЧЕТВЕРГ!S5 -> 0 | J33: =ЧЕТВЕРГ!T5 -> 0 | ... AI33: =ЧЕТВЕРГ!AS5 -> 0 | AJ33: =#REF! -> #REF!
B34: 5 | C34: =ЧЕТВЕРГ!M6 -> 0 | D34: =ЧЕТВЕРГ!N6 -> 0 | E34: =ЧЕТВЕРГ!O6 -> Биология/406 | F34: =ЧЕТВЕРГ!P6 -> 0 | G34: =ЧЕТВЕРГ!Q6 -> 0 | H34: =ЧЕТВЕРГ!R6 -> 0 | I34: =ЧЕТВЕРГ!S6 -> 0 | J34: =ЧЕТВЕРГ!T6 -> 0 | ... AI34: =ЧЕТВЕРГ!AS6 -> 0 | AJ34: =#REF! -> #REF!
C35: пт | D35: пт | E35: пт | F35: пт | G35: пт | H35: пт | I35: пт | J35: пт | K35: пт | L35: пт | M35: пт | N35: пт | O35: пт | P35: пт | Q35: пт | R35: пт | S35: пт | T35: пт | U35: пт | V35: пт | W35: пт | X35: пт | Y35: пт | Z35: пт | AA35: пт | AB35: пт | AC35: пт | AD35: пт | AE35: пт | AF35: пт | AG35: пт | AH35: пт | AI35: пт | AJ35: пт
A36: ПЯТНИЦА | B36: 1 | C36: =ПЯТНИЦА!M3 -> 0 | D36: =ПЯТНИЦА!N3 -> 0 | E36: =ПЯТНИЦА!O3 -> Аналит.хим./256 | F36: =ПЯТНИЦА!P3 -> 0 | G36: =ПЯТНИЦА!Q3 -> 0 | H36: =ПЯТНИЦА!R3 -> 0 | I36: =ПЯТНИЦА!S3 -> 0 | J36: =ПЯТНИЦА!T3 -> 0 | ... AI36: =ПЯТНИЦА!AS3 -> 0 | AJ36: =ПЯТНИЦА!B36 -> 0
B37: 2 | C37: =ПЯТНИЦА!M4 -> 0 | D37: =ПЯТНИЦА!N4 -> 0 | E37: =ПЯТНИЦА!O4 -> БЖД/231 | F37: =ПЯТНИЦА!P4 -> 0 | G37: =ПЯТНИЦА!Q4 -> 0 | H37: =ПЯТНИЦА!R4 -> 0 | I37: =ПЯТНИЦА!S4 -> 0 | J37: =ПЯТНИЦА!T4 -> 0 | ... AI37: =ПЯТНИЦА!AS4 -> 0 | AJ37: =ПЯТНИЦА!C36 -> 0
B38: 3 | C38: =ПЯТНИЦА!M5 -> 0 | D38: =ПЯТНИЦА!N5 -> 0 | E38: =ПЯТНИЦА!O5 -> Биология/228 | F38: =ПЯТНИЦА!P5 -> 0 | G38: =ПЯТНИЦА!Q5 -> 0 | H38: =ПЯТНИЦА!R5 -> 0 | I38: =ПЯТНИЦА!S5 -> 0 | J38: =ПЯТНИЦА!T5 -> 0 | ... AI38: =ПЯТНИЦА!AS5 -> 0 | AJ38: =ПЯТНИЦА!D36 -> 0
A39: =ПЯТНИЦА!D1 -> 46311 | B39: 4 | C39: =ПЯТНИЦА!M6 -> 0 | D39: =ПЯТНИЦА!N6 -> 0 | E39: =ПЯТНИЦА!O6 -> Биология/406 | F39: =ПЯТНИЦА!P6 -> 0 | G39: =ПЯТНИЦА!Q6 -> 0 | H39: =ПЯТНИЦА!R6 -> 0 | I39: =ПЯТНИЦА!S6 -> 0 | J39: =ПЯТНИЦА!T6 -> 0 | ... AI39: =ПЯТНИЦА!AS6 -> 0 | AJ39: =ПЯТНИЦА!E36 -> ПМ03/418
B40: 5 | C40: =ПЯТНИЦА!M7 -> 0 | D40: =ПЯТНИЦА!N7 -> 0 | E40: =ПЯТНИЦА!O7 -> Выбор оборуд./309 | F40: =ПЯТНИЦА!P7 -> 0 | G40: =ПЯТНИЦА!Q7 -> 0 | H40: =ПЯТНИЦА!R7 -> 0 | I40: =ПЯТНИЦА!S7 -> 0 | J40: =ПЯТНИЦА!T7 -> 0 | ... AI40: =ПЯТНИЦА!AS7 -> 0 | AJ40: =ПЯТНИЦА!F36 -> МДК 01.02/401
C41: сб | D41: сб | E41: сб | F41: сб | G41: сб | H41: сб | I41: сб | J41: сб | K41: сб | L41: сб | M41: сб | N41: сб | O41: сб | P41: сб | Q41: сб | R41: сб | S41: сб | T41: сб | U41: сб | V41: сб | W41: сб | X41: сб | Y41: сб | Z41: сб | AA41: сб | AB41: сб | AC41: сб | AD41: сб | AE41: сб | AF41: сб | AG41: сб | AH41: сб | AI41: сб | AJ41: сб
A42: СУББОТА | B42: 1 | C42: =СУББОТА!M3 -> 0 | D42: =СУББОТА!N3 -> 0 | E42: =СУББОТА!O3 -> Аналит.хим./256 | F42: =СУББОТА!P3 -> 0 | G42: =СУББОТА!Q3 -> 0 | H42: =СУББОТА!R3 -> 0 | I42: =СУББОТА!S3 -> 0 | J42: =СУББОТА!T3 -> 0 | ... AI42: =СУББОТА!AS3 -> 0 | AJ42: =СУББОТА!B36 -> Кар.мод./304
B43: 2 | C43: =СУББОТА!M4 -> 0 | D43: =СУББОТА!N4 -> 0 | E43: =СУББОТА!O4 -> БЖД/231 | F43: =СУББОТА!P4 -> 0 | G43: =СУББОТА!Q4 -> 0 | H43: =СУББОТА!R4 -> 0 | I43: =СУББОТА!S4 -> 0 | J43: =СУББОТА!T4 -> 0 | ... AI43: =СУББОТА!AS4 -> 0 | AJ43: =СУББОТА!C36 -> ПМ02/227(М)
...

Sheet ПОНЕДЕЛЬНИК
B1: ПОНЕДЕЛЬНИК | D1: 46307
A2: Группа | B2: 1 пара | C2: 2 пара | D2: 3 пара | E2: 4 пара | F2: 5 пара | G2: 6 пара
A3: 102тс | B3: Физика/104 | C3: Математика/227 | D3: История/310 | O3: Аналит.хим./256
A4: 104эм | B4: Иностран. язык/312/314 | C4: Русский язык/228 | D4: Химия/406 | O4: БЖД/231
A5: 136э | B5: Биология/228 | C5: Физика/416 | D5: Математика/405 | O5: Биология/228
A6: 137э | B6: Математика/405 | C6: Русский язык/404 | D6: Информатика/226 | O6: Биология/406
A7: 138э | B7: Проект.деят/411(Щ) | C7: Математика/405 | D7: Биология/228 | O7: Выбор оборуд./309
A8: 139э | B8: Физика/416 | C8: История/310 | D8: Проект.деят/317(Б) | O8: География/201
A9: 181р | B9: Физика/300 | C9: Физика/300 | D9: Русский язык/404 | O9: Геодезия/201
A10: 182р | B10: Русский язык/404 | C10: Математика/419 | D10: Иностран. язык/312/б-ка | O10: Гидравлика/101
A11: 183р | B11: Математика/227 | C11: Информатика/400 | D11: Обществознание/411 | O11: Гидрология/228
A12: 184р | B12: Информатика/400 | C12: Обществознание/411 | D12: Математика/227 | O12: Измер.техн./308
A13: 175т | B13: История/310 | C13: Биология/406 | D13: Физика/104 | O13: Инж.граф./421
A14: 176т | B14: Биология/406 | C14: Физика/104 | D14: География/201 | O14: Инж.граф./423
... A16: 124ос | B16: Математика/419 | C16: География/201 | D16: Физика/416 | O16: Иностр.яз./316
A17: 201тс | D17: Физкультура | E17: Математика/419 | F17: ТОТ/101 | G17: Осн. фин. грамот./418 | O17: Иностр.яз./410/316
A18: 202эм | C18: Инж.граф./421 | D18: Охрана труда/318 | E18: Эл.матер./317 | O18: Иностран. язык/312/316
A19: 203эм | D19: Иностр.яз./314 | E19: Охрана труда/318 | F19: Эл.матер./317 | O19: Иностран. язык/410
A20: 232э | C20: История/233 | D20: Информатика/400 | E20: Тех.мех./421 | O20: Иностран. язык/410/312
A21: 233э | E21: Культура речи/401 | F21: История/233 | G21: Материаловед./317 | O21: Информат. в ПД/361
A22: 234э | D22: Физкультура | E22: История/233 | F22: Культура речи/401 | O22: Информат. в ПД/361/358
A23: 278р | D23: Инж.граф./421 | E23: Ин. язык/314/231 | F23: Электротехника/300 | O23: Информат. в ПД/362
A24: 279р | D24: Электротехника/300 | E24: Математика/227 | F24: Материаловед./310(С) | O24: Информат. в ПД/362/358
A25: 180ру | E25: Электротехника/300 | F25: Инж.граф./421 | G25: Материалов./310(С) | O25: Информатика/361
A26: 185ру | E26: Материалов./310(С) | F26: Математика/419 | G26: Электротехника/300 | O26: Информатика/361/358
A27: 273т | E27: Материаловед./104 | F27: Осн. фин. грамот./418 | G27: ТОТ/101 | O27: Информатика/362
A28: 222ос | C28: ПМ 01/327 | D28: ПМ 01/327 | E28: Информатика/400 | O28: Информатика/362/358
A29: 329э | D29: ПМ 02/231(Т) | E29: ПМ 06/327(Х) | F29: ПМ 06/327(Х) | O29: История/233
A30: 330э | E30: ПМ03/423 | F30: ПМ03/423 | G30: ПМ 06/327(Х) | O30: История/310
A31: 375р | B31: ПРАКТИКА | C31: ПРАКТИКА | D31: ПРАКТИКА | O31: Кар.мод./256
A32: 376р | E32: Осн. экономики/418 | F32: ПМ 03/231(Т) | G32: Охрана труда/318 | O32: Кар.мод./304
A33: 277ру | E33: Иностр.яз./312 | F33: Охрана труда/318 | G33: ПМ 03/309(М) | O33: Кар.мод./418
A34: 372т | D34: Осн. экономики/418 | E34: ПМ 02/308 | F34: ПМ 02/308 | O34: Культура речи/417
A35: 321ос | E35: ПМ03/201 | F35: ПМ03/201 | G35: ПМ03/201 | O35: Литература/404
A36: 425э | B36: Психология/401 | C36: ПМ03/423 | D36: ПМ 01/301(К) | O36: Литература/417
A37: 426э | B37: ПМ 01/301(К) | C37: Психология/401 | D37: ПМ03/423 | O37: Математика/227
A38: 427э | B38: ПМ03/423 | C38: ПМ 01/301(К) | D38: Психология/401 | O38: Математика/405
A39: 472р | B39: Физкультура | C39: Психология/304 | D39: ПМ 01/309(М) | O39: Математика/416
A40: 473р | B40: Психология/304 | C40: ПМ 01/309(М) | D40: Правовые осн ПД/304 | O40: Математика/419
A41: 471т | B41: ПМ03/308 | C41: ПМ03/308 | D41: ПМ04/101 | E41: ПМ04/101 | O41: Материаловед./317
...

Sheet ВТОРНИК
B1: ВТОРНИК | D1: 46308
A2: Группа | B2: 1 пара | C2: 2 пара | D2: 3 пара | E2: 4 пара | F2: 5 пара | G2: 6 пара
A3: 102тс | B3: География/201 | C3: Русский язык/327 | D3: Математика/227 | O3: Аналит.хим./256
A4: 104эм | B4: История/310 | C4: Обществознание/233 | D4: Проект.деят/233(Щ) | O4: БЖД/231
A5: 136э | B5: Физика/416 | C5: Биология/228 | D5: Информатика/226 | O5: Биология/228
A6: 137э | B6: Литература/404 | C6: Информатика/226 | D6: Математика/405 | O6: Биология/406
A7: 138э | B7: Математика/405 | C7: История/310 | D7: Проект.деят/б-ка(Б) | O7: Выбор оборуд./309
A8: 139э | B8: Литература/406 | C8: Математика/405 | D8: Физика/416 | O8: География/201
A9: 181р | B9: Информатика/400 | C9: Литература/404 | D9: История/310 | O9: Геодезия/201
A10: 182р | B10: Биология/228 | C10: Математика/419 | D10: Литература/404 | O10: Гидравлика/101
A11: 183р | B11: Математика/227 | C11: Информатика/400 | D11: Биология/228 | O11: Гидрология/228
A12: 184р | B12: Ин. язык/314/411 | C12: Математика/227 | D12: География/201 | O12: Измер.техн./308
A13: 175т | B13: Обществознание/233 | C13: География/201 | D13: Русский язык/327 | O13: Инж.граф./421
A14: 176т | B14: Русский язык/327 | C14: ОБЗР/231 | D14: Физика/104 | O14: Инж.граф./423
... A16: 124ос | B16: Математика/419 | C16: Русский язык/406 | D16: Химия/231 | O16: Иностр.яз./316
A17: 201тс | D17: ТОТ/101 | E17: Материаловед./104 | F17: Материаловед./104 | O17: Иностр.яз./410/316
A18: 202эм | C18: Тех.мех./421 | D18: Слес.раб./304 | E18: БЖД/231 | O18: Иностран. язык/312/316
A19: 203эм | B19: Эл. машины/300 | C19: Слес.раб./304 | D19: Инж.граф./423 | O19: Иностран. язык/410
A20: 232э | D20: Электротехника/301 | E20: Ин. язык/312/314 | F20: Культура речи/406 | O20: Иностран. язык/410/312
A21: 233э | E21: Электротехника/301 | F21: Ин. язык/312/314 | G21: Тех.мех./421 | O21: Информат. в ПД/361
A22: 234э | D22: Информатика/400 | E22: Тех.мех./421 | F22: Электротехн/301 | O22: Информат. в ПД/361/358
A23: 278р | D23: Ин. язык/314/411 | E23: Материалов./310(С) | F23: Математика/419 | G23: Материалов./310(С) | O23: Информат. в ПД/362
A24: 279р | C24: Ин. язык/314/411 | D24: Физкультура | E24: Электротехника/300 | O24: Информат. в ПД/362/358
A25: 180ру | C25: Электротехника/300 | D25: Инж.граф./421 | E25: Физкультура | F25: Материалов./310(С) | O25: Информатика/361
A26: 185ру | D26: Электротехника/300 | E26: Информатика/400 | F26: Метрология/327 | G26: Инж.граф./423 | O26: Информатика/361/358
A27: 273т | D27: Математика/419 | E27: ТОТ/101 | F27: Инж.граф./421 | O27: Информатика/362
A28: 222ос | D28: Осн. фин. грамот./418 | E28: Математика/419 | F28: Почвоведение/228 | G28: Метрология/327 | O28: Информатика/362/358
A29: 329э | E29: ПМ 04/317(К) | F29: ПМ 02/231(Т) | G29: ПМ 06/416(Х) | O29: История/233
A30: 330э | D30: ПМ 04/317(К) | E30: ПМ 06/416(Х) | F30: ПМ 06/416(Х) | O30: История/310
A31: 375р | B31: ПРАКТИКА | C31: ПРАКТИКА | D31: ПРАКТИКА | O31: Кар.мод./256
A32: 376р | C32: ПМ 01/309(М) | D32: Охрана труда/323 | E32: Осн. экономики/418 | O32: Кар.мод./304
A33: 277ру | E33: ПМ 04/233(Р) | F33: Осн. экон./418 | G33: Охрана труда/318 | O33: Кар.мод./418
A34: 372т | E34: ПМ03/308 | F34: ПМ03/308 | G34: Осн. экономики/418 | O34: Культура речи/417
A35: 321ос | E35: ПМ 02/201 | F35: ПМ 02/201 | G35: ПМ 02/201 | O35: Литература/404
A36: 425э | F36: ПМ05/318 | G36: МДК 01.01(О) 401/6,7п | O36: Литература/417
A37: 426э | F37: Кар.мод./304 | G37: МДК 01.01(О) 401/6,7п | O37: Математика/227
A38: 427э | F38: ПМ 01/317(К) | G38: МДК 01.01(О) 401/6,7п | O38: Математика/405
A39: 472р | B39: Энергосбер./423 | C39: ПМ 03/401 | D39: ПМ 01/309(М) | O39: Математика/416
A40: 473р | B40: ПМ 01/309(М) | C40: Энергосбер./423 | D40: ПМ 03/401 | E40: ПМ 03/401 | O40: Математика/419
A41: 471т | B41: ПМ04/101 | C41: ПМ04/101 | D41: Психология/100 | O41: Материаловед./317
...

Sheet СРЕДА
B1: СРЕДА | D1: 46309
A2: Группа | B2: 1 пара | C2: 2 пара | D2: 3 пара | E2: 4 пара | F2: 5 пара | G2: 6 пара
A3: 102тс | B3: Математика/227 | C3: Биология/406 | D3: Химия/406 | O3: Аналит.хим./256
A4: 104эм | E4: Информатика/226 | F4: Математика/416 | G4: Математика/416 | O4: БЖД/231
A5: 136э | B5: Ин. язык/312/314 | C5: Математика/405 | D5: Обществознание/411 | O5: Биология/228
A6: 137э | B6: История/233 | C6: Информатика/226 | D6: Математика/405 | O6: Биология/406
A7: 138э | B7: Математика/405 | C7: Физкультура | D7: Информатика/226 | O7: Выбор оборуд./309
A8: 139э | B8: Информатика/400 | C8: История/310 | D8: Литература/404 | O8: География/201
A9: 181р | B9: География/201 | C9: Обществознание/411 | D9: Биология/228 | O9: Геодезия/201
A10: 182р | B10: ОБЗР/231 | C10: География/201 | D10: История/310 | E10: История/310 | O10: Гидравлика/101
A11: 183р | B11: Биология/228 | C11: Математика/227 | D11: География/201 | O11: Гидрология/228
A12: 184р | B12: Обществознание/411 | C12: Биология/228 | D12: Математика/227 | O12: Измер.техн./308
A13: 175т | B13: Биология/406 | C13: ОБЗР/231 | D13: Обществознание/100 | O13: Инж.граф./421
A14: 176т | B14: Физкультура | C14: Обществознание/318 | D14: Русский язык/310 | O14: Инж.граф./423
A15: 123ос | B15: История/310 | C15: Математика/419 | D15: Информатика/400 | O15: Иностр.яз./312
A16: 124ос | B16: Математика/419 | C16: Информатика/400 | D16: Проект.деят/327 | O16: Иностр.яз./316
A17: 201тс | B17: Тех.мех./421 | C17: Иностр.яз./314 | D17: Математика/419 | E17: Физкультура | O17: Иностр.яз./410/316
A18: 202эм | C18: Слес.раб./104 | D18: МДК01.01/318(Х) | E18: Иностр.яз./314 | O18: Иностран. язык/312/316
A19: 203эм | C19: Тех.мех./421 | D19: Слес.раб./104 | E19: МДК01.01/404(Х) | F19: Информатика/226 | O19: Иностран. язык/410
A20: 232э | C20: зз | E20: Инж.граф./423 | F20: Электротехника/301 | G20: Материаловед./317 | O20: Иностран. язык/410/312
A21: 233э | D21: Физкультура | E21: Электротехника/301 | F21: Инж.граф./423 | O21: Информат. в ПД/361
A22: 234э | D22: Электротехника/301 | E22: Ин. язык/312/411 | F22: Материаловед./317 | G22: Инж.граф./423 | O22: Информат. в ПД/361/358
A23: 278р | D23: Инж.граф./421 | E23: Математика/419 | F23: Электротехника/300 | G23: Материалов./310(С) | O23: Информат. в ПД/362
A24: 279р | E24: Электротехника/300 | F24: Математика/227 | G24: Инж.граф./421 | O24: Информат. в ПД/362/358
A25: 180ру | D25: Ин. язык/312/314 | E25: Информатика/400 | F25: Математика/419 | G25: Электротех/300 | O25: Информатика/361
A26: 185ру | C26: Иностр.яз./312 | D26: Электротехника/300 | E26: Тех.мех./421 | F26: Материалов./310(С) | O26: Информатика/361/358
A27: 273т | D27: Физкультура | E27: Осн. фин. грамот./418 | F27: Инж.граф./421 | O27: Информатика/362
A28: 222ос | D28: БЖД/231 | E28: Геодезия/201 | F28: Осн. фин. гр./418 | O28: Информатика/362/358
A29: 329э | D29: Физкультура | E29: ПМ 04/317(К) | F29: ПМ 06/404(Х) | O29: История/233
A30: 330э | E30: ПМ 01/304(Ш) | F30: ПМ 01/304(Ш) | G30: ПМ 06/404(Х) | O30: История/310
A31: 375р | B31: ПРАКТИКА | C31: ПРАКТИКА | D31: ПРАКТИКА | E31: ПМ03/318(Д) | O31: Кар.мод./256
A32: 376р | D32: ПМ 03/233(Т) | E32: ПМ 01/416(М) | F32: ПМ03/318(Д) | O32: Кар.мод./304
A33: 277ру | D33: Осн. экономики/418 | E33: Физкультура | F33: ПМ 01/233(М) | G33: ПМ03/318(Д) | O33: Кар.мод./418
A34: 372т | D34: ПМ 01/309(1) | E34: ПМ 01/309 | F34: ПМ 01/309 | G34: ПМ 01/309(2) | O34: Культура речи/417
A35: 321ос | E35: ПРАКТИКА | F35: ПРАКТИКА | G35: ПРАКТИКА | O35: Литература/404
A36: 425э | B36: ПМ03/423 | C36: Физкультура | D36: ПМ 01/317(К) | O36: Литература/417
A37: 426э | B37: ПМ 01/317(К) | C37: ПМ03/423 | D37: ПМ 02/416(М) | O37: Математика/227
A38: 427э | B38: Психология/318 | C38: ПМ 01/317(К) | D38: ПМ03/423 | O38: Математика/405
A39: 472р | B39: ПМ 03/401 | C39: ПМ 03/401 | D39: Правовые осн ПД/304 | O39: Математика/416
A40: 473р | B40: ПМ 01/416(М) | C40: ПМ 01/416(М) | D40: ПМ 03/401 | O40: Математика/419
...

Sheet ЧЕТВЕРГ
B1: ЧЕТВЕРГ | D1: 46310
A2: Группа | B2: 1 пара | C2: 2 пара | D2: 3 пара | E2: 4 пара | F2: 5 пара | G2: 6 пара
A3: 102тс | B3: Литература/227 | C3: ОБЗР/231 | D3: Физкультура | O3: Аналит.хим./256
A4: 104эм | B4: Физкультура | C4: География/201 | D4: Обществознание/304 | O4: БЖД/231
A5: 136э | B5: История/233 | C5: Физика/416 | D5: Русский язык/404 | O5: Биология/228
A6: 137э | B6: Ин. язык/312/314 | C6: История/233 | D6: Проект.деят/б-ка(Б) | O6: Биология/406
A7: 138э | B7: Русский язык/404 | C7: Ин. язык/312/314 | D7: Физика/416 | O7: Выбор оборуд./309
A8: 139э | B8: Физика/416 | C8: Биология/228 | D8: Ин. язык/312/314 | O8: География/201
A9: 181р | B9: География/201 | C9: Математика/419 | D9: История/310 | E9: История/310 | O9: Геодезия/201
A10: 182р | B10: Биология/228 | C10: Информатика/400 | D10: География/201 | O10: Гидравлика/101
A11: 183р | B11: Информатика/400 | C11: Русский язык/404 | D11: Биология/228 | O11: Гидрология/228
A12: 184р | B12: История/310 | C12: Литература/227 | D12: Русский язык/227 | O12: Измер.техн./308
A13: 175т | E13: Информатика/226 | F13: География/201 | G13: Физкультура | O13: Инж.граф./421
A14: 176т | B14: Иностр.яз./406 | C14: История/310 | D14: Информатика/226 | O14: Инж.граф./423
A15: 123ос | B15: Математика/419 | C15: Литература/406 | D15: ОБЗР/231 | O15: Иностр.яз./312
A16: 124ос | B16: ОБЗР/231 | C16: Физкультура | D16: Литература/406 | O16: Иностр.яз./316
A17: 201тс | C17: Инж.граф./421 | D17: Материаловед./104 | E17: ТОТ/101 | F17: Осн. фин. грамот./418 | O17: Иностр.яз./410/316
A18: 202эм | C18: Слес.раб./300 | D18: Слес.раб./300 | E18: История/233 | F18: Информатика/400 | O18: Иностран. язык/312/316
A19: 203эм | D19: Тех.мех./421 | E19: Слес.раб./305 | F19: История/233 | O19: Иностран. язык/410
A20: 232э | E20: Электротехника/301 | F20: Инж.граф./423 | G20: Математика/405 | O20: Иностран. язык/410/312
A21: 233э | C21: Инж.граф./423 | D21: Электротехника/301 | E21: Информатика/400 | F21: Математика/405 | O21: Информат. в ПД/361
A22: 234э | D22: История/411 | E22: Математика/405 | F22: Электротехника/301 | G22: Инж.граф./423 | O22: Информат. в ПД/361/358
A23: 278р | D23: Информатика/400 | E23: Тех.мех./421 | F23: Культура речи/406 | O23: Информат. в ПД/362
A24: 279р | E24: Культура речи/406 | F24: Тех.мех./421 | G24: История/233 | O24: Информат. в ПД/362/358
A25: 180ру | F25: Математика/419 | G25: Тех.мех./421 | O25: Информатика/361
A26: 185ру | E26: Математика/419 | F26: Культура речи/310 | O26: Информатика/361/358
A27: 273т | B27: ТОТ/101 | C27: ТОТ/101 | D27: Математика/419 | E27: Материаловед./104 | O27: Информатика/362
A28: 222ос | D28: Осн. фин. грамот./418 | E28: Геодезия/201 | F28: Гидрология/228 | O28: Информатика/362/358
A29: 329э | D29: ПМ 04/317(К) | E29: ПМ 04/317(К) | F29: ПМ 02/201 (Т) | O29: История/233
A30: 330э | D30: ПМ03/423 | E30: ПМ 01/300(Ш) | F30: ПМ 01/300(Ш) | O30: История/310
A31: 375р | B31: ПРАКТИКА | C31: ПРАКТИКА | D31: ПРАКТИКА | E31: ПМ03/318(Д) | O31: Кар.мод./256
A32: 376р | D32: ПМ 02/233(Р) | E32: Физкультура | F32: ПМ03/318(Д) | G32: Охрана труда/318 | O32: Кар.мод./304
A33: 277ру | E33: Осн. экономики/418 | F33: Охрана труда/318 | G33: ПМ03/318(Д) | O33: Кар.мод./418
A34: 372т | C34: ПМ 01/309 (2) | D34: ПМ 01/309 | E34: ПМ 01/309 | F34: ПМ 01/309 (1) | O34: Культура речи/417
A35: 321ос | E35: ПРАКТИКА | F35: ПРАКТИКА | G35: ПРАКТИКА | O35: Литература/404
A36: 425э | F36: ПМ 02/416 (М) | G36: МДК 01.01(О) 401/6,7п | O36: Литература/417
A37: 426э | F37: Физкультура | G37: МДК 01.01(О) 401/6,7п | O37: Математика/227
A38: 427э | E38: ПМ03/423 | F38: Кар.мод./304 | G38: МДК 01.01(О) 401/6,7п | O38: Математика/405
A39: 472р | C39: ПМ 01/304 (М) | D39: ПМ04/318 | E39: ПМ 03/401 | O39: Математика/416
A40: 473р | B40: ПМ 03/401 | C40: ПМ 03/401 | D40: ПМ 03/401 | E40: ПМ 01/308 (М) | O40: Математика/419
...

Sheet ПЯТНИЦА
B1: ПЯТНИЦА | D1: 46311
A2: Группаи | B2: 1 пара | C2: 2 пара | D2: 3 пара | E2: 4 пара | F2: 5 пара | G2: 6 пара
A3: 102тс | B3: История/310 | C3: Обществознание/405 | D3: Биология/406 | O3: Аналит.хим./256
A4: 104эм | B4: Физкультура | C4: Биология/406 | D4: ОБЗР/104 | O4: БЖД/231
A5: 136э | B5: География/201 | C5: Литература/404 | D5: Физкультура | O5: Биология/228
A6: 137э | B6: Обществознание/411 | C6: Физкультура | D6: Биология/228 | O6: Биология/406
A7: 138э | B7: Физика/416 | C7: ОБЗР/104 | D7: Информатика/400 | O7: Выбор оборуд./309
A8: 139э | B8: ОБЗР/104 | C8: Биология/228 | D8: География/201 | O8: География/201
A9: 181р | B9: Математика/419 | C9: Обществознание/411 | D9: География/201 | O9: Геодезия/201
A10: 182р | B10: ОБЗР/231 | C10: Математика/419 | D10: Обществознание/411 | O10: Гидравлика/101
A11: 183р | B11: Литература/404 | C11: История/310 | D11: Русский язык/404 | O11: Гидрология/228
A12: 184р | B12: Биология/228 | C12: География/201 | D12: История/310 | O12: Измер.техн./308
A13: 175т | B13: Биология/406 | C13: Физкультура | D13: Обществознание/405 | O13: Инж.граф./421
A14: 176т | E14: Информатика/400 | F14: Математика/416 | G14: Математика/416 | O14: Инж.граф./423
A15: 123ос | B15: Обществознание/405 | C15: Физика/416 | D15: Физкультура | O15: Иностр.яз./312
A16: 124ос | B16: Иностр.яз./312 | C16: Физкультура | D16: Физика/416 | O16: Иностр.яз./316
A17: 201тс | C17: ТОТ/101 | D17: ТОТ/101 | E17: ТОТ/101 | O17: Иностр.яз./410/316
A18: 202эм | E18: МДК 01.01/411(Х) | F18: Инж.граф./421 | G18: Охрана труда/318 | O18: Иностран. язык/312/316
A19: 203эм | C19: Слес.раб./301 | D19: МДК 01.01/304(Х) | E19: Инж.граф./423 | O19: Иностран. язык/410
A20: 232э | E20: Материаловед./317 | F20: Электротехника/301 | G20: Математика/405 | O20: Иностран. язык/410/312
A21: 233э | E21: Электротехника/301 | F21: Математика/405 | G21: Материаловед./317 | O21: Информат. в ПД/361
A22: 234э | D22: Электротехника/301 | E22: Математика/405 | F22: Материаловед./317 | O22: Информат. в ПД/361/358
A23: 278р | E23: История/233 | F23: Математика/419 | G23: Электротехника/300 | O23: Информат. в ПД/362
A24: 279р | D24: Электротехника/300 | E24: Метрология/327 | F24: Информатика/400 | G24: Тех.мех./421 | O24: Информат. в ПД/362/358
A25: 180ру | D25: Математика/419 | E25: Электротехника/300 | F25: История/233 | O25: Информатика/361
A26: 185ру | D26: Инж.граф./423 | E26: Тех.мех./421 | F26: Электротехника/300 | G26: История/233 | O26: Информатика/361/358
A27: 273т | D27: Ин. язык/312/314 | E27: Математика/419 | F27: ТОТ/101 | G27: ТОТ/101 | O27: Информатика/362
A28: 222ос | C28: Ин. язык/312/314 | D28: ПМ 01/327 | E28: Почвоведение/204 | F28: Осн. фин. гр./418 | O28: Информатика/362/358
A29: 329э | D29: ПМ 04/418(К) | E29: ПМ 02/231 (Т) | F29: ПМ03/423 | O29: История/233
A30: 330э | D30: ПМ 02/231 (Т) | E30: Физкультура | F30: ПМ 04/231(К) | O30: История/310
A31: 375р | B31: ПРАКТИКА | C31: ПРАКТИКА | D31: ПРАКТИКА | O31: Кар.мод./256
A32: 376р | E32: ПМ 01/310 (М) | F32: Охрана труда/318 | G32: Осн. экономики/418 | O32: Кар.мод./304
A33: 277ру | E33: Охрана труда/404 | F33: ПМ 03/310 (М) | G33: Физкультура | O33: Кар.мод./418
A34: 372т | E34: ПМ 02/308 | F34: ПМ 01/309 | G34: ПМ 01/309 | O34: Культура речи/417
A35: 321ос | E35: Прав. основы ПД/304 | F35: ПМ 02/201 | G35: ПМ 03/201 | O35: Литература/404
A36: 425э | E36: ПМ03/418 | F36: МДК 01.02/401 | G36: ПМ03/423 | O36: Литература/417
A37: 426э | F37: МДК 01.02/401 | G37: ПМ 01/231 (К) | O37: Математика/227
A38: 427э | E38: ПМ05/318 | F38: Физкультура | G38: МДК 01.02/401 | O38: Математика/405
A39: 472р | B39: ПМ 03/401 | C39: ПМ 03/401 | D39: ПМ 01/233 (М) | O39: Математика/416
A40: 473р | B40: Физкультура | C40: ПМ04/318 | D40: ПМ 03/401 | O40: Математика/419
...

Sheet СУББОТА
B1: СУББОТА | D1: 46312
A2: Группа | B2: 1 пара | C2: 2 пара | D2: 3 пара | E2: 4 пара | F2: 5 пара | G2: 6 пара
A3: 102тс | B3: Химия/(Д) | C3: Иностран. язык/(Д) | D3: Математика/(Д) | O3: Аналит.хим./256
A4: 104эм | B4: Математика/(Д) | C4: Химия/(Д) | D4: Биология/(Д) | O4: БЖД/231
A5: 136э | B5: Проект.деят/(Д)(Б) | C5: Обществознание/(Д) | D5: Физика/(Д) | O5: Биология/228
A6: 137э | B6: География/(Д) | C6: Физика/(Д) | D6: Биология/(Д) | O6: Биология/406
A7: 138э | B7: Обществознание/(Д) | C7: Биология/(Д) | D7: География/(Д) | E7: Физика/(Д) | O7: Выбор оборуд./309
A8: 139э | B8: Физика/(Д) | C8: География/(Д) | D8: Иностран. язык/(Д) | O8: География/201
A9: 181р | B9: Информатика/(Д) | C9: Математика/(Д) | D9: Обществознание/(Д) | O9: Геодезия/201
A10: 182р | B10: Математика/(Д) | C10: Информатика/(Д) | D10: Литература/(Д) | O10: Гидравлика/101
A11: 183р | B11: Математика/(Д) | C11: Литература/(Д) | D11: ОБЗР/(Д) | O11: Гидрология/228
A12: 184р | B12: ОБЗР/(Д) | C12: История/(Д) | D12: Информатика/(Д) | O12: Измер.техн./308
A13: 175т | B13: Иностран. язык/(Д) | C13: Математика/(Д) | D13: Обществознание/(Д) | O13: Инж.граф./421
A14: 176т | B14: История/(Д) | C14: ОБЗР/(Д) | D14: Математика/(Д) | E14: Биология/(Д) | O14: Инж.граф./423
A15: 123ос | B15: Проект.деят/(Д) | C15: Обществознание/(Д) | D15: Математика/(Д) | O15: Иностр.яз./312
A16: 124ос | B16: Обществознание/(Д) | C16: Проект.деят/(Д) | D16: История/(Д) | E16: Математика/(Д) | O16: Иностр.яз./316
A17: 201тс | B17: Осн. фин. гр./418 | C17: Материалов./104 | D17: Инж.граф./421 | O17: Иностр.яз./410/316
A18: 202эм | B18: Информатика/400 | C18: Охрана труда/318 | D18: МДК01.01/416(Х) | O18: Иностран. язык/312/316
A19: 203эм | B19: МДК01.01/416(Х) | C19: Информатика/400 | D19: Охрана труда/318 | O19: Иностран. язык/410
A20: 232э | B20: История/233 | C20: Математика/405 | D20: Материаловед./317 | O20: Иностран. язык/410/312
A21: 233э | B21: Материаловед./317 | C21: История/233 | D21: Математика/405 | O21: Информат. в ПД/361
A22: 234э | B22: Математика/405 | C22: Материаловед./317 | D22: Культура речи/406 | O22: Информат. в ПД/361/358
A23: 278р | B23: Материаловед./310(С) | C23: Электротехника/300 | D23: История/233 | O23: Информат. в ПД/362
A24: 279р | C24: Тех.мех./421 | D24: Информатика/400 | E24: Электротехника/300 | O24: Информат. в ПД/362/358
A25: 180ру | B25: Электротехника/300 | C25: Материаловед./310(С) | D25: Материаловед./310(С) | O25: Информатика/361
A26: 185ру | C26: Электротехника/300 | D26: Электротехника/300 | E26: Материалов./310(С) | O26: Информатика/361/358
A27: 273т | B27: Тех.мех./421 | C27: ТОТ/101 | D27: Материаловед./104 | O27: Информатика/362
A28: 222ос | B28: Физкультура | C28: Метрология/327 | D28: Геодезия/201 | O28: Информатика/362/358
A29: 329э | B29: ПМ 02/231(Т) | C29: ПМ 06/416(Х) | D29: Иностр.яз./227 | O29: История/233
A30: 330э | C30: Иностр.яз./227 | D30: ПМ 02/231(Т) | E30: ПМ 06/416(Х) | O30: История/310
A31: 375р | B31: ПРАКТИКА | C31: ПРАКТИКА | D31: ПРАКТИКА | O31: Кар.мод./256
A32: 376р | C32: Осн. экономики/418 | D32: ПМ 01/301(М) | E32: Иностр.яз./227 | O32: Кар.мод./304
A33: 277ру | C33: ПМ 01/227(Т) | D33: Осн. экономики/418 | E33: ПМ 03/301(М) | O33: Кар.мод./418
A34: 372т | B34: Иностр.яз./227 | C34: ПМ 02/308 | D34: ПМ 02/308 | O34: Культура речи/417
A35: 321ос | B35: Охрана труда/318 | C35: ПМ 02/304 | D35: ПМ 03/304 | O35: Литература/404
A36: 425э | B36: Кар.мод./304 | C36: ПМ02/227(М) | D36: Физкультура | O36: Литература/417
A37: 426э | B37: Физкультура | C37: Психология/406 | D37: ПМ03/423 | O37: Математика/227
A38: 427э | B38: ПМ01/228(К) | C38: Физкультура | D38: ПМ03/423 | O38: Математика/405
A39: 472р | B39: ПМ 01/301(М) | C39: ПМ 03/401 | D39: ПМ 03/401 | O39: Математика/416
A40: 473р | B40: ПМ 03/401 | C40: ПМ 01/301(М) | O40: Математика/419
...
